<?xml version = "1.0" ?>
<robot name="Alex">

	<!-- The pelvis is the frame underneath the center of the AMR, equidistant from all wheels. The wheel frame link, if you will. -->
	<link name="WheelFrame">
		<inertial>
			<mass value="0"/>
			<origin rpy="0 0 0" xyz="0 0 0"/>
			<inertia ixx="0.0" ixy="0.0" ixz="0.0" iyy="0.0" iyz="0.0" izz="0.0" />
		</inertial>
<!--		<visual>-->
<!--			<geometry>-->
<!--				<mesh filename="package://agile_x_ranger_amr_description/meshes/Agile_X_Ranger_Base.obj"/>-->
<!--			</geometry>-->
<!--			<origin rpy="0.0 0.0 0.0" xyz="0.0 0.0 0.0"/>-->
<!--		</visual>-->
	</link>
	
	<!-- Pelvis IMU -->
	<link name="PelvisIMULink">
		<inertial>
			<mass value="0"/>
			<origin rpy="0 0 0" xyz="0 0 0"/>
			<inertia ixx="0.0" ixy="0.0" ixz="0.0" iyy="0.0" iyz="0.0" izz="0.0"/>
		</inertial>
	</link>
	<joint name="PelvisIMUJoint" type="fixed">
		<origin xyz="-0.08544739 -0.01922816 0.05317309" rpy="0.0 0.0 0.0"/>
		<axis xyz="0 0 1"/>
		<parent link="Chassis"/>
		<child link="PelvisIMULink"/>
	</joint>
	<gazebo reference="PelvisIMULink">
		<sensor name="PelvisIMU" type="imu">
			<always_on>true</always_on>
			<imu>
				<noise>
					<type>gaussian</type>
					<rate>
						<mean>0</mean>
						<stddev>0.0002</stddev>
						<bias_mean>7.5e-06</bias_mean>
						<bias_stddev>8e-07</bias_stddev>
					</rate>
					<accel>
						<mean>0</mean>
						<stddev>0.017</stddev>
						<bias_mean>0.1</bias_mean>
						<bias_stddev>0.001</bias_stddev>
					</accel>
				</noise>
			</imu>
		</sensor>
	</gazebo>

	<!-- AMR -->
	<joint name="WheelFrameToChassisFixedJoint" type="fixed">
		<origin rpy="0 0 0" xyz="0	 	0	 0.336" />
		<axis xyz="0 0 1" />
		<parent link="WheelFrame" />
		<child link="Chassis" />
		<limit effort="500" lower="0.0" upper="0.7" velocity = "1.0" />
		<dynamics damping="0.05" friction="0.0"/>
	</joint>
	<link name="Chassis">
		<inertial>
			<!-- Mass, CoM, and Inertia are made up values. -->
			<mass value="80.0"/>
			<origin rpy="0 0 0" xyz="0.0 0.0 0.0"/>
			<inertia ixx="0.5" ixy="0.0" ixz="0.5" iyy="0.0" iyz="0.0" izz="0.5"/>
		</inertial>
		<visual>
			<geometry>
				<mesh filename="package://agile_x_ranger_amr_description/meshes/Agile_X_Ranger_Base.obj"/>
			</geometry>
			<origin rpy="0.0 0.0 0.0" xyz="0.0 0.0 0.0"/>
		</visual>
	</link>

	<!-- Front Left Wheel-->
	<joint name="FrontLeftWheelYaw" type="fixed">
		<origin rpy="0 0 0" xyz="0.445	 	0.280	 0" />
		<axis xyz="0 0 1" />
		<parent link="Chassis" />
		<child link="FrontLeftWheelYawLink" />
		<limit effort="500" lower="0.0" upper="0.7" velocity = "1.0" />
		<dynamics damping="0.05" friction="0.0"/>
	</joint>
	<link name="FrontLeftWheelYawLink">
		<inertial>
			<!-- Mass, CoM, and Inertia are made up values. -->
			<mass value="2.0"/>
			<origin rpy="0 0 0" xyz="0.0 0.0 0.0"/>
			<inertia ixx="0.05" ixy="0.0" ixz="0.05" iyy="0.0" iyz="0.0" izz="0.05"/>
		</inertial>
		<visual>
			<geometry>
				<mesh filename="package://agile_x_ranger_amr_description/meshes/Ranger_Wheel_Mount.obj"/>
			</geometry>
			<origin rpy="0.0 0.0 3.14159" xyz="0.0 0.0 0.0"/>
		</visual>
	</link>
	<joint name="FrontLeftWheelRotation" type="fixed">
		<origin rpy="0 0 0" xyz="0.0		0.003	 -0.180" />
		<axis xyz="0 1 0" />
		<parent link="FrontLeftWheelYawLink" />
		<child link="FrontLeftWheelRotationLink" />
		<limit effort="500" lower="0.0" upper="0.7" velocity = "1.0" />
		<dynamics damping="0.05" friction="0.0"/>
	</joint>
	<link name="FrontLeftWheelRotationLink">
		<inertial>
			<!-- Mass, CoM, and Inertia are made up values. -->
			<mass value="3.0"/>
			<origin rpy="0 0 0" xyz="0.0 0.0 0.0"/>
			<inertia ixx="0.05" ixy="0.0" ixz="0.05" iyy="0.0" iyz="0.0" izz="0.05"/>
		</inertial>
		<visual>
			<geometry>
				<mesh filename="package://agile_x_ranger_amr_description/meshes/Ranger_Wheel.obj"/>
			</geometry>
			<origin rpy="0.0 0.0 0.0" xyz="0.0 0.0 0.0"/>
		</visual>
	</link>

	<!-- Front Right Wheel-->
	<joint name="FrontRightWheelYaw" type="fixed">
		<origin rpy="0 0 0" xyz="0.445	 	-0.280	 0" />
		<axis xyz="0 0 1" />
		<parent link="Chassis" />
		<child link="FrontRightWheelYawLink" />
		<limit effort="500" lower="0.0" upper="0.7" velocity = "1.0" />
		<dynamics damping="0.05" friction="0.0"/>
	</joint>
	<link name="FrontRightWheelYawLink">
		<inertial>
			<!-- Mass, CoM, and Inertia are made up values. -->
			<mass value="2.0"/>
			<origin rpy="0 0 0" xyz="0.0 0.0 0.0"/>
			<inertia ixx="0.05" ixy="0.0" ixz="0.05" iyy="0.0" iyz="0.0" izz="0.05"/>
		</inertial>
		<visual>
			<geometry>
				<mesh filename="package://agile_x_ranger_amr_description/meshes/Ranger_Wheel_Mount.obj"/>
			</geometry>
			<origin rpy="0.0 0.0 0.0" xyz="0.0 0.0 0.0"/>
		</visual>
	</link>
	<joint name="FrontRightWheelRotation" type="fixed">
		<origin rpy="0 0 0" xyz="0.0 	0.0	 -0.180" />
		<axis xyz="0 1 0" />
		<parent link="FrontRightWheelYawLink" />
		<child link="FrontRightWheelRotationLink" />
		<limit effort="500" lower="0.0" upper="0.7" velocity = "1.0" />
		<dynamics damping="0.05" friction="0.0"/>
	</joint>
	<link name="FrontRightWheelRotationLink">
		<inertial>
			<!-- Mass, CoM, and Inertia are made up values. -->
			<mass value="3.0"/>
			<origin rpy="0 0 0" xyz="0.0 0.0 0.0"/>
			<inertia ixx="0.05" ixy="0.0" ixz="0.05" iyy="0.0" iyz="0.0" izz="0.05"/>
		</inertial>
		<visual>
			<geometry>
				<mesh filename="package://agile_x_ranger_amr_description/meshes/Ranger_Wheel.obj"/>
			</geometry>
			<origin rpy="0.0 0.0 0.0" xyz="0.0 0.0 0.0"/>
		</visual>
	</link>

	<!-- Back Left Wheel-->
	<joint name="BackLeftWheelYaw" type="fixed">
		<origin rpy="0 0 0" xyz="-0.445	 	0.280	 0" />
		<axis xyz="0 0 1" />
		<parent link="Chassis" />
		<child link="BackLeftWheelYawLink" />
		<limit effort="500" lower="0.0" upper="0.7" velocity = "1.0" />
		<dynamics damping="0.05" friction="0.0"/>
	</joint>
	<link name="BackLeftWheelYawLink">
		<inertial>
			<!-- Mass, CoM, and Inertia are made up values. -->
			<mass value="2.0"/>
			<origin rpy="0 0 0" xyz="0.0 0.0 0.0"/>
			<inertia ixx="0.05" ixy="0.0" ixz="0.05" iyy="0.0" iyz="0.0" izz="0.05"/>
		</inertial>
		<visual>
			<geometry>
				<mesh filename="package://agile_x_ranger_amr_description/meshes/Ranger_Wheel_Mount.obj"/>
			</geometry>
			<origin rpy="0.0 0.0 3.14159" xyz="0.0 0.0 0.0"/>
		</visual>
	</link>
	<joint name="BackLeftWheelRotation" type="fixed">
		<origin rpy="0 0 0" xyz="0.0 		0.0	 -0.180" />
		<axis xyz="0 1 0" />
		<parent link="BackLeftWheelYawLink" />
		<child link="BackLeftWheelRotationLink" />
		<limit effort="500" lower="0.0" upper="0.7" velocity = "1.0" />
		<dynamics damping="0.05" friction="0.0"/>
	</joint>
	<link name="BackLeftWheelRotationLink">
		<inertial>
			<!-- Mass, CoM, and Inertia are made up values. -->
			<mass value="3.0"/>
			<origin rpy="0 0 0" xyz="0.0 0.0 0.0"/>
			<inertia ixx="0.05" ixy="0.0" ixz="0.05" iyy="0.0" iyz="0.0" izz="0.05"/>
		</inertial>
		<visual>
			<geometry>
				<mesh filename="package://agile_x_ranger_amr_description/meshes/Ranger_Wheel.obj"/>
			</geometry>
			<origin rpy="0.0 0.0 0.0" xyz="0.0 0.0 0.0"/>
		</visual>
	</link>

	<!-- Back Right Wheel-->
	<joint name="BackRightWheelYaw" type="fixed">
		<origin rpy="0 0 0" xyz="-0.445	 	-0.280	 0" />
		<axis xyz="0 0 1" />
		<parent link="Chassis" />
		<child link="BackRightWheelYawLink" />
		<limit effort="500" lower="0.0" upper="0.7" velocity = "1.0" />
		<dynamics damping="0.05" friction="0.0"/>
	</joint>
	<link name="BackRightWheelYawLink">
		<inertial>
			<!-- Mass, CoM, and Inertia are made up values. -->
			<mass value="2.0"/>
			<origin rpy="0 0 0" xyz="0.0 0.0 0.0"/>
			<inertia ixx="0.05" ixy="0.0" ixz="0.05" iyy="0.0" iyz="0.0" izz="0.05"/>
		</inertial>
		<visual>
			<geometry>
				<mesh filename="package://agile_x_ranger_amr_description/meshes/Ranger_Wheel_Mount.obj"/>
			</geometry>
			<origin rpy="0.0 0.0 0.0" xyz="0.0 0.0 0.0"/>
		</visual>
	</link>
	<joint name="BackRightWheelRotation" type="fixed">
		<origin rpy="0 0 0" xyz="0.0 	0.0	 -0.180" />
		<axis xyz="0 1 0" />
		<parent link="BackRightWheelYawLink" />
		<child link="BackRightWheelRotationLink" />
		<limit effort="500" lower="0.0" upper="0.7" velocity = "1.0" />
		<dynamics damping="0.05" friction="0.0"/>
	</joint>
	<link name="BackRightWheelRotationLink">
		<inertial>
			<!-- Mass, CoM, and Inertia are made up values. -->
			<mass value="3.0"/>
			<origin rpy="0 0 0" xyz="0.0 0.0 0.0"/>
			<inertia ixx="0.05" ixy="0.0" ixz="0.05" iyy="0.0" iyz="0.0" izz="0.05"/>
		</inertial>
		<visual>
			<geometry>
				<mesh filename="package://agile_x_ranger_amr_description/meshes/Ranger_Wheel.obj"/>
			</geometry>
			<origin rpy="0.0 0.0 0.0" xyz="0.0 0.0 0.0"/>
		</visual>
	</link>


	<!-- Spine Joints -->
	<joint name="SpineHeight" type="prismatic">
		<!-- To avoid changing so many offsets, this frame is floating in space where the original torso frame was (0.693460 - 0.307953). -->
		<origin rpy="0 0 0" xyz="0.687	 0.0	 0.385507" />
		<axis xyz="0 0 1" />
		<parent link="Chassis" />
		<child link="Torso" />
		<limit effort="500" lower="0.0" upper="0.7" velocity = "1.0" />
		<dynamics damping="0.05" friction="0.0"/>
    </joint>

	<!-- ZED 2 in the Torso, taken quickly from Onshape, offset from Left J1, needs to be checked -->
	<joint name="ZEDTorsoCameraMount" type="fixed">
		<origin xyz="0.125449 0.00337060  0.21927127" rpy="-1.919866 	 0		-1.5708"/>
		<axis xyz="0 0 1"/>
		<parent link="Torso"/>
		<child link="ZedCameraLink"/>
	</joint>
	<link name="ZedCameraLink">
		<inertial>
			<mass value="0"/>
			<origin rpy="0 0 0" xyz="0 0 0"/>
			<inertia ixx="0.0" ixy="0.0" ixz="0.0" iyy="0.0" iyz="0.0" izz="0.0"/>
		</inertial>
	</link>
	<gazebo reference="ZedCameraLink">
		<sensor name="ZedCamera" type="camera">
			<update_rate>60.0</update_rate>
			<camera>
				<pose>0 0 0 0 0 0</pose>
				<horizontal_fov>2.0</horizontal_fov>
				<image>
					<width>1280</width>
					<height>1024</height>
					<format>R8G8B8</format>
				</image>
				<clip>
					<near>0.02</near>
					<far>300</far>
				</clip>
				<noise>
					<type>gaussian</type>
					<mean>0.0</mean>
					<stddev>0.007</stddev>
				</noise>
			</camera>
		</sensor>
	</gazebo>

	<!-- Torso Link -->
	<link name="Torso">
		<inertial>
			<mass value="17.574"/>
			<origin rpy="0 0 0" xyz="0.003673 0.000059 0.160289"/>
			<inertia ixx="0.24725248" ixy="-0.000080922" ixz="0.000927935" iyy="0.158680043" iyz="0.000328726" izz="0.153487995"/>
		</inertial>
		<visual>
			<geometry>
				<mesh filename="package://phantom_description/meshes/ALX02_02_A06_TorsoLink.obj"/>
			</geometry>
			<origin rpy="0.0 0.0 0.0" xyz="0.0 0.0 0.0"/>
		</visual>
	</link>

	<!-- TORSO IMU's NOTE: The torso IMUs are redundant-->
	<!-- Torso Left IMU. Currently not used for anything-->
	<link name="TorsoLeftIMULink">
		<inertial>
			<mass value="0"/>
			<origin rpy="0 0 0" xyz="0 0 0"/>
			<inertia ixx="0.0" ixy="0.0" ixz="0.0" iyy="0.0" iyz="0.0" izz="0.0"/>
		</inertial>
	</link>
	<joint name="TorsoLeftIMUJoint" type="fixed">
		<origin rpy="1.5707963267948966 -0.6981317007977316 1.5707963267948961" xyz="0.07978495 0.10932294 0.17623744"/>
		<axis xyz="0 0 1"/>
		<parent link="Torso"/>
		<child link="TorsoLeftIMULink"/>
	</joint>
	<gazebo reference="TorsoLeftIMULink">
		<sensor name="TorsoLeftIMU" type="imu">
			<always_on>true</always_on>
			<imu>
				<noise>
					<type>gaussian</type>
					<rate>
						<mean>0</mean>
						<stddev>0.0002</stddev>
						<bias_mean>7.5e-06</bias_mean>
						<bias_stddev>8e-07</bias_stddev>
					</rate>
					<accel>
						<mean>0</mean>
						<stddev>0.017</stddev>
						<bias_mean>0.1</bias_mean>
						<bias_stddev>0.001</bias_stddev>
					</accel>
				</noise>
			</imu>
		</sensor>
	</gazebo>

	<!-- Torso Right IMU. Currently not used for anything-->
	<link name="TorsoRightIMULink">
		<inertial>
			<mass value="0"/>
			<origin rpy="0 0 0" xyz="0 0 0"/>
			<inertia ixx="0.0" ixy="0.0" ixz="0.0" iyy="0.0" iyz="0.0" izz="0.0"/>
		</inertial>
	</link>
	<joint name="TorsoRightIMUJoint" type="fixed">
		<origin rpy="1.5707963267948966 0.6981317007977319 1.5707963267948966" xyz="0.07978495 -0.09055680 0.16048643"/>
		<axis xyz="0 0 1"/>
		<parent link="Torso"/>
		<child link="TorsoRightIMULink"/>
	</joint>
	<gazebo reference="TorsoRightIMULink">
		<sensor name="TorsoRightIMU" type="imu">
			<always_on>true</always_on>
			<imu>
				<noise>
					<type>gaussian</type>
					<rate>
						<mean>0</mean>
						<stddev>0.0002</stddev>
						<bias_mean>7.5e-06</bias_mean>
						<bias_stddev>8e-07</bias_stddev>
					</rate>
					<accel>
						<mean>0</mean>
						<stddev>0.017</stddev>
						<bias_mean>0.1</bias_mean>
						<bias_stddev>0.001</bias_stddev>
					</accel>
				</noise>
			</imu>
		</sensor>
	</gazebo>

	<!-- TorsoIMULink-->
	<!-- this is an IMU on top of the Neck yaw motor controller board-->
	<link name="TorsoIMULink">
		<inertial>
			<mass value="0"/>
			<origin rpy="0 0 0" xyz="0 0 0"/>
			<inertia ixx="0.0" ixy="0.0" ixz="0.0" iyy="0.0" iyz="0.0" izz="0.0"/>
		</inertial>
	</link>
	<joint name="TorsoIMUJoint" type="fixed">
		<origin rpy="0 0 -1.5707963267948966" xyz="0.00399725 -0.01225021 0.24512039"/>
		<axis xyz="0 0 1"/>
		<parent link="Torso"/>
		<child link="TorsoIMULink"/>
	</joint>
	<gazebo reference="TorsoIMULink">
		<sensor name="TorsoIMU" type="imu">
			<always_on>true</always_on>
			<imu>
				<noise>
					<type>gaussian</type>
					<rate>
						<mean>0</mean>
						<stddev>0.0002</stddev>
						<bias_mean>7.5e-06</bias_mean>
						<bias_stddev>8e-07</bias_stddev>
					</rate>
					<accel>
						<mean>0</mean>
						<stddev>0.017</stddev>
						<bias_mean>0.1</bias_mean>
						<bias_stddev>0.001</bias_stddev>
					</accel>
				</noise>
			</imu>
		</sensor>
	</gazebo>

	<!-- Neck Joints -->
	<joint name="NeckYaw" type="revolute">
		<origin rpy="0 0 0" xyz="0 0 0.307953" /> <!-- placeholder for the joint location -->
		<axis xyz="0 0 1" />
		<parent link="Torso" />
		<child link="NeckYawLink" />
		<limit effort="20" lower="-1.5708" upper="1.5708" velocity = "20" />
		<dynamics damping="0.05" friction="0.0"/>
	</joint>

	<joint name="NeckPitch" type="revolute">
		<origin rpy="0 0 0" xyz="0.025 0.01 0.207252" />
		<axis xyz="0 1 0" />
		<parent link="NeckYawLink" />
		<child link="Head" />
		<limit effort="20" lower="-0.49524" upper="0.48023" velocity = "20" />
		<dynamics damping="0.05" friction="0.0"/>
	</joint>

	<!--	 Neck and Head -->
	<!--	 Inertia data is a placeholder -->
	<link name="NeckYawLink">
		<inertial>
			<mass value="1.141"/>
			<origin rpy="0 0 0" xyz="0.007143 0.006943 0.109823"/>
			<inertia ixx="0.007475898" ixy="-0.000075723" ixz="-0.000745362" iyy="0.007407578" iyz="-0.000436948" izz="0.00109269" />
		</inertial>
		<visual>
			<geometry>
				<mesh filename="package://phantom_description/meshes/ALX02_01_A03_NeckLink.obj"/>
			</geometry>
			<origin rpy="0.0 0.0 0.0" xyz="0.0 0.0 0.0"/>
		</visual>
	</link>

	<link name="Head">
		<inertial>
			<mass value="1.677"/>
			<origin rpy="0 0 0" xyz="0.03237 -0.013568 0.007163"/>
			<inertia ixx="0.006026191" ixy="-0.000197484" ixz="0.001813659" iyy="0.008182071" iyz="-0.000042529" izz="0.00644909"/>
		</inertial>
		<visual>
			<geometry>
				<mesh filename="package://phantom_description/meshes/ALX02_01_A02_HeadLink.obj"/>
			</geometry>
			<origin rpy="0.0 0.0 0.0" xyz="0.0 0.0 0.0"/>
		</visual>
	</link>

	<!-- Head Cameras (assuming camera lens is x-forward) -->
	<!-- Front Top Camera -->
	<joint name="FrontTopCameraMount" type="fixed">
		<origin xyz="0.136322	-0.010140	 0.024795" rpy="-1.692973	0	-1.5708"/>
		<axis xyz="0 0 1"/>
		<parent link="Head"/>
		<child link="FrontTopCameraLink"/>
	</joint>
	<link name="FrontTopCameraLink">
		<inertial>
			<mass value="0"/>
			<origin rpy="0 0 0" xyz="0 0 0"/>
			<inertia ixx="0.0" ixy="0.0" ixz="0.0" iyy="0.0" iyz="0.0" izz="0.0"/>
		</inertial>
	</link>
	<gazebo reference="FrontTopCameraLink">
		<sensor name="FrontTopCamera" type="camera">
			<update_rate>60.0</update_rate>
<!--			name="FrontTopCamera"-->
			<camera>
				<pose>0 0 0 0 0 0</pose>
				<horizontal_fov>2.0</horizontal_fov>
				<image>
					<width>1280</width>
					<height>1024</height>
					<format>R8G8B8</format>
				</image>
				<clip>
					<near>0.02</near>
					<far>300</far>
				</clip>
				<noise>
					<type>gaussian</type>
					<mean>0.0</mean>
					<stddev>0.007</stddev>
				</noise>
			</camera>
		</sensor>
	</gazebo>

	<!-- Front Bottom Camera -->
	<joint name="FrontBottomCameraMount" type="fixed">
		<origin xyz="0.127182	-0.010140	 -0.049646" rpy="-1.692973	0	-1.5708"/>
		<axis xyz="0 0 1"/>
		<parent link="Head"/>
		<child link="FrontBottomCameraLink"/>
	</joint>
	<link name="FrontBottomCameraLink">
		<inertial>
			<mass value="0"/>
			<origin rpy="0 0 0" xyz="0 0 0"/>
			<inertia ixx="0.0" ixy="0.0" ixz="0.0" iyy="0.0" iyz="0.0" izz="0.0"/>
		</inertial>
	</link>
	<gazebo reference="FrontBottomCameraLink">
		<sensor name="FrontBottomCamera" type="camera">
			<update_rate>60.0</update_rate>
			<camera>
				<pose>0 0 0 0 0 0</pose>
				<horizontal_fov>2.0</horizontal_fov>
				<image>
					<width>1280</width>
					<height>1024</height>
					<format>R8G8B8</format>
				</image>
				<clip>
					<near>0.02</near>
					<far>300</far>
				</clip>
				<noise>
					<type>gaussian</type>
					<mean>0.0</mean>
					<stddev>0.007</stddev>
				</noise>
			</camera>
		</sensor>
	</gazebo>

	<!-- Front Left Camera -->
	<joint name="FrontLeftCameraMount" type="fixed">
		<origin xyz="0.125558	0.033155	 -0.010" rpy="-1.5708		0	-1.047201"/>
		<axis xyz="0 0 1"/>
		<parent link="Head"/>
		<child link="FrontLeftCameraLink"/>
	</joint>
	<link name="FrontLeftCameraLink">
		<inertial>
			<mass value="0"/>
			<origin rpy="0 0 0" xyz="0 0 0"/>
			<inertia ixx="0.0" ixy="0.0" ixz="0.0" iyy="0.0" iyz="0.0" izz="0.0"/>
		</inertial>
	</link>
	<gazebo reference="FrontLeftCameraLink">
		<sensor name="FrontLeftCamera" type="camera">
			<update_rate>60.0</update_rate>
			<camera>
				<pose>0 0 0 0 0 0</pose>
				<horizontal_fov>2.0</horizontal_fov>
				<image>
					<width>1280</width>
					<height>1024</height>
					<format>R8G8B8</format>
				</image>
				<clip>
					<near>0.02</near>
					<far>300</far>
				</clip>
				<noise>
					<type>gaussian</type>
					<mean>0.0</mean>
					<stddev>0.007</stddev>
				</noise>
			</camera>
		</sensor>
	</gazebo>

	<!-- Front Right Camera -->
	<joint name="FrontRightCameraMount" type="fixed">
		<origin xyz="0.125558	-0.053655	 -0.010" rpy="-1.5708		0	-2.094399 "/>
		<axis xyz="0 0 1"/>
		<parent link="Head"/>
		<child link="FrontRightCameraLink"/>
	</joint>
	<link name="FrontRightCameraLink">
		<inertial>
			<mass value="0"/>
			<origin rpy="0 0 0" xyz="0 0 0"/>
			<inertia ixx="0.0" ixy="0.0" ixz="0.0" iyy="0.0" iyz="0.0" izz="0.0"/>
		</inertial>
	</link>
	<gazebo reference="FrontRightCameraLink">
		<sensor name="FrontRightCamera" type="camera">
			<update_rate>60.0</update_rate>
			<camera>
				<pose>0 0 0 0 0 0</pose>
				<horizontal_fov>2.0</horizontal_fov>
				<image>
					<width>1280</width>
					<height>1024</height>
					<format>R8G8B8</format>
				</image>
				<clip>
					<near>0.02</near>
					<far>300</far>
				</clip>
				<noise>
					<type>gaussian</type>
					<mean>0.0</mean>
					<stddev>0.007</stddev>
				</noise>
			</camera>
		</sensor>
	</gazebo>

	<!-- Side Left Camera -->
	<joint name="SideLeftCameraMount" type="fixed">
		<origin xyz="0.018	0.07156	 0.025" rpy="-1.5708	 0 	0"/>
		<axis xyz="0 0 1"/>
		<parent link="Head"/>
		<child link="SideLeftCameraLink"/>
	</joint>
	<link name="SideLeftCameraLink">
		<inertial>
			<mass value="0"/>
			<origin rpy="0 0 0" xyz="0 0 0"/>
			<inertia ixx="0.0" ixy="0.0" ixz="0.0" iyy="0.0" iyz="0.0" izz="0.0"/>
		</inertial>
	</link>
	<gazebo reference="SideLeftCameraLink">
		<sensor name="SideLeftCamera" type="camera">
			<update_rate>60.0</update_rate>
			<camera>
				<pose>0 0 0 0 0 0</pose>
				<horizontal_fov>2.0</horizontal_fov>
				<image>
					<width>1280</width>
					<height>1024</height>
					<format>R8G8B8</format>
				</image>
				<clip>
					<near>0.02</near>
					<far>300</far>
				</clip>
				<noise>
					<type>gaussian</type>
					<mean>0.0</mean>
					<stddev>0.007</stddev>
				</noise>
			</camera>
		</sensor>
	</gazebo>

	<!-- Side Right Camera -->
	<joint name="SideRightCameraMount" type="fixed">
		<origin xyz="0.018	-0.092060	 0.025" rpy="-1.5708	 0 	3.14159"/>
		<axis xyz="0 0 1"/>
		<parent link="Head"/>
		<child link="SideRightCameraLink"/>
	</joint>
	<link name="SideRightCameraLink">
		<inertial>
			<mass value="0"/>
			<origin rpy="0 0 0" xyz="0 0 0"/>
			<inertia ixx="0.0" ixy="0.0" ixz="0.0" iyy="0.0" iyz="0.0" izz="0.0"/>
		</inertial>
	</link>
	<gazebo reference="SideRightCameraLink">
		<sensor name="SideRightCamera" type="camera">
			<update_rate>60.0</update_rate>
			<camera>
				<pose>0 0 0 0 0 0</pose>
				<horizontal_fov>2.0</horizontal_fov>
				<image>
					<width>1280</width>
					<height>1024</height>
					<format>R8G8B8</format>
				</image>
				<clip>
					<near>0.02</near>
					<far>300</far>
				</clip>
				<noise>
					<type>gaussian</type>
					<mean>0.0</mean>
					<stddev>0.007</stddev>
				</noise>
			</camera>
		</sensor>
	</gazebo>

	<!-- Back Left Camera -->
	<joint name="BackLeftCameraMount" type="fixed">
		<origin xyz="-0.064303		0.018136	 0.075110" rpy="-1.5708		 0		 1.221734"/>
		<axis xyz="0 0 1"/>
		<parent link="Head"/>
		<child link="BackLeftCameraLink"/>
	</joint>
	<link name="BackLeftCameraLink">
		<inertial>
			<mass value="0"/>
			<origin rpy="0 0 0" xyz="0 0 0"/>
			<inertia ixx="0.0" ixy="0.0" ixz="0.0" iyy="0.0" iyz="0.0" izz="0.0"/>
		</inertial>
	</link>
	<gazebo reference="BackLeftCameraLink">
		<sensor name="BackLeftCamera" type="camera">
			<update_rate>60.0</update_rate>
			<camera>
				<pose>0 0 0 0 0 0</pose>
				<horizontal_fov>2.0</horizontal_fov>
				<image>
					<width>1280</width>
					<height>1024</height>
					<format>R8G8B8</format>
				</image>
				<clip>
					<near>0.02</near>
					<far>300</far>
				</clip>
				<noise>
					<type>gaussian</type>
					<mean>0.0</mean>
					<stddev>0.007</stddev>
				</noise>
			</camera>
		</sensor>
	</gazebo>

	<!-- Back Left Camera -->
	<joint name="BackRightCameraMount" type="fixed">
		<origin xyz="-0.064303		-0.038636	 0.075110" rpy="-1.5708		 0		 1.919866"/>
		<axis xyz="0 0 1"/>
		<parent link="Head"/>
		<child link="BackRightCameraLink"/>
	</joint>
	<link name="BackRightCameraLink">
		<inertial>
			<mass value="0"/>
			<origin rpy="0 0 0" xyz="0 0 0"/>
			<inertia ixx="0.0" ixy="0.0" ixz="0.0" iyy="0.0" iyz="0.0" izz="0.0"/>
		</inertial>
	</link>
	<gazebo reference="BackRightCameraLink">
		<sensor name="BackRightCamera" type="camera">
			<update_rate>60.0</update_rate>
			<camera>
				<pose>0 0 0 0 0 0</pose>
				<horizontal_fov>2.0</horizontal_fov>
				<image>
					<width>1280</width>
					<height>1024</height>
					<format>R8G8B8</format>
				</image>
				<clip>
					<near>0.02</near>
					<far>300</far>
				</clip>
				<noise>
					<type>gaussian</type>
					<mean>0.0</mean>
					<stddev>0.007</stddev>
				</noise>
			</camera>
		</sensor>
	</gazebo>

	<!-- LEFT ARM -->
	<!-- left upper arm joints -->
	<joint name="LeftShoulderPitch" type="revolute">
		<origin xyz="0 0.10337060 0.21502827" rpy="0.698132 0.0 0.0"   />
		<axis xyz="0.0 1.0 0.0" />
		<parent link="Torso" />
		<child link="LeftShoulderPitchLink" />
		<limit effort="150.0" lower="-3.141592" upper="1.22173" velocity = "9.0" />
		<dynamics damping="0.05" friction="0.0"/>
	</joint>

	<joint name="LeftShoulderRoll" type="revolute">
		<origin rpy="-0.698132 0.0 0.0" xyz="0.0 0.15676000 -0.01300000" />
		<axis xyz="1 0 0" />
		<parent link="LeftShoulderPitchLink" />
		<child link="LeftShoulderRollLink" />
		<limit effort="150.0" lower="-0.349066" upper="2.79253" velocity = "9.0" />
		<dynamics damping="0.05" friction="0.0"/>
	</joint>

	<joint name="LeftShoulderYaw" type="revolute">
		<origin rpy="0.0 0.0 0.0" xyz="0.0 0.035 0.0" />
		<axis xyz="0.0 0.0 1.0" />
		<parent link="LeftShoulderRollLink" />
		<child link="LeftShoulderYawLink" />
		<limit effort="80.0" lower="-1.91986" upper="1.22173" velocity = "11.5" />
		<dynamics damping="0.05" friction="0.0"/>
	</joint>

	<joint name="LeftElbowPitch" type="revolute">
		<origin rpy="0.0 0.0 0.0" xyz="0.015 0.0 -0.3127" />
		<axis xyz="0.0 1.0 0.0" />
		<parent link="LeftShoulderYawLink" />
		<child link="LeftElbowPitchLink" />
		<limit effort="80.0" lower="-2.35619" upper="0.174532925" velocity = "11.5" />
		<dynamics damping="0.05" friction="0.0"/>
	</joint>

	<!-- left wrist joints -->
	<joint name="LeftWristYaw" type="revolute">
		<origin xyz="-0.015 0.0 0.0" rpy="0.0 0.0 0.0"   />
		<axis xyz="0.0 0.0 1.0" />
		<parent link="LeftElbowPitchLink" />
		<child link="LeftWristYawLink" />
		<limit effort="20.0" lower="-2.61799" upper="2.61799" velocity = "25.0" />
		<dynamics damping="0.05" friction="0.0"/>
	</joint>

	<joint name="LeftWristRoll" type="revolute">
		<origin xyz="0.0 -0.013 -0.25" rpy="0.0 0.0 0.0"/>
		<axis xyz="1 0 0" />
		<parent link="LeftWristYawLink" />
		<child link="LeftWristRollLink" />
		<limit effort="20.0" lower="-1.8326" upper="0.610865" velocity = "25.0" />
		<dynamics damping="0.05" friction="0.0"/>
	</joint>

	<joint name="LeftGripperYaw" type="revolute">
		<origin xyz="0.0 0.013 -0.031" rpy="0.0 0.0 0.0" />
		<axis xyz="0.0 0.0 1.0" />
		<parent link="LeftWristRollLink" />
		<child link="LeftGripperYawLink" />
		<limit effort="20.0" lower="-2.61799" upper="2.61799" velocity = "25.0" />
		<dynamics damping="0.05" friction="0.0"/>
	</joint>

	<!-- left upper arm links -->
	<link name="LeftShoulderPitchLink">
		<inertial>
			<mass value="2.99"/>
			<origin
					rpy="0 0 0"
					xyz="-0.00264 0.12135 -0.006824"/>
			<inertia ixx="0.0111046" ixy="0.0002882" ixz="-0.000054" iyy="0.0051699" iyz="0.0009318" izz="0.01176" />
		</inertial>
		<visual>
			<geometry>
				<mesh filename="package://phantom_description/meshes/cycloidal_arm/LeftShoulderPitchLink.obj"/>
			</geometry>
			<origin rpy="0.0 0.0 0.0" xyz="0.0 0.0 0.0"/>
		</visual>
	</link>

	<link name="LeftShoulderRollLink">
		<inertial>
			<mass value="0.972"/>
			<origin
					rpy="0 0 0"
					xyz="0.01251711 0.0188309 -0.03849849"/>
			<inertia ixx="0.0029485" ixy="0.0001386" ixz="-0.0003345" iyy="0.0023587" iyz="0.0005255" izz="0.0014366" />
		</inertial>
		<visual>
			<geometry>
				<mesh filename="package://phantom_description/meshes/cycloidal_arm/LeftShoulderRollLink_shortBicep.obj"/>
			</geometry>
			<origin rpy="0.0 0.0 0.0" xyz="0.0 0.0 0.0"/>
		</visual>
	</link>

	<link name="LeftShoulderYawLink">
		<inertial>
			<mass value="2.91"/>
			<origin
					rpy="0 0 0"
					xyz="0.00510403 0.00314332 -0.21695413"/>
			<inertia ixx="0.0267829" ixy="-0.000011" ixz="0.0015998" iyy="0.0265514" iyz="0.0004426" izz="0.003052" />
		</inertial>
		<visual>
			<geometry>
				<mesh filename="package://phantom_description/meshes/cycloidal_arm/LeftShoulderYawLink.obj"/>
			</geometry>
			<origin rpy="0.0 0.0 0.0" xyz="0.0 0.0 0.0867"/>
		</visual>
	</link>

	<!-- left wrist links -->
	<link name="LeftElbowPitchLink">
		<inertial>
			<mass value="0.45"/>
			<origin
					rpy="0 0 0"
					xyz="-0.01180322 -0.0035763 -0.04946747"/>

			<inertia ixx="0.0007362" ixy="-0.0000088" ixz="-0.0000292" iyy="0.0006567" iyz="0.0001499" izz="0.0004897" />
		</inertial>
		<visual>
			<geometry>
				<mesh filename="package://phantom_description/meshes/cycloidal_arm/LeftElbowPitchLink.obj"/>
			</geometry>
			<origin rpy="0.0 0.0 0.0" xyz="0.0 0.0 0.0"/>
		</visual>
	</link>

	<link name="LeftWristYawLink">
		<inertial>
			<mass value="1.547"/> <!-- This is a measured value. Refer to https://docs.google.com/spreadsheets/d/1VXWFJk3VJUsfkHrDaytB2INq94un1KytIOzcKJD0p44/edit?gid=0#gid=0  -->
			<origin
					rpy="0 0 0"
					xyz="-0.00263832 -0.00050534 -0.13018376"/>

			<inertia ixx="0.0037869" ixy="0.0000163" ixz="-0.0000252" iyy="0.004071" iyz="-0.0000924" izz="0.0015203" />
		</inertial>
		<visual>
			<geometry>
				<mesh filename="package://phantom_description/meshes/cycloidal_arm/LeftWristYawLink.obj"/>
			</geometry>
			<origin rpy="0.0 0.0 0.0" xyz="0.0 0.0 0.0"/>
		</visual>
	</link>


	<link name="LeftWristRollLink">
		<inertial>
			<mass value="0.909"/> <!-- This is a measured value. Refer to https://docs.google.com/spreadsheets/d/1VXWFJk3VJUsfkHrDaytB2INq94un1KytIOzcKJD0p44/edit?gid=0#gid=0  -->
			<origin
					rpy="0 0 0"
					xyz="0.00004053 0.01038395 0.00035532"/>

			<inertia ixx="0.000477" ixy="-0.0000079" ixz="-0.0000097" iyy="0.0004902" iyz="-0.0000008" izz="0.000514" />
		</inertial>

		<visual>
			<geometry>
				<mesh filename="package://phantom_description/meshes/cycloidal_arm/LeftWristRollLink.obj"/>
			</geometry>
			<origin rpy="0.0 0.0 0.0" xyz="0.0 0.0 0.0"/>
		</visual>
	</link>


	<link name="LeftGripperYawLink">
		<inertial>
			<mass value="0.251"/>
			<origin
					rpy="0 0 0"
					xyz="-0.000217 -0.000349 0.009761"/>
			<inertia ixx="0.0000722" ixy="-0.0000016" ixz="-0.0000037" iyy="0.0000747" iyz="0.0000004" izz="0.0000324" />
		</inertial>
		<visual>
			<geometry>
				<mesh filename="package://phantom_description/meshes/cycloidal_arm/LeftGripperYawLink.obj"/>
			</geometry>
			<origin rpy="0.0 0.0 0.0" xyz="0.0 0.0 0.0"/>
		</visual>
	</link>

	<!-- LEFT ARM IMU's -->
	<!-- Left Shoulder Pitch IMU Information -->
	<link name="LeftShoulderPitchIMULink">
		<inertial>
			<mass value="0"/>
			<origin rpy="0 0 0" xyz="0 0 0"/>
			<inertia ixx="0.0" ixy="0.0" ixz="0.0" iyy="0.0" iyz="0.0" izz="0.0"/>
		</inertial>
	</link>
	<joint name="LeftShoulderPitchIMUJoint" type="fixed">
		<origin rpy="-3.141592 0 -1.57079632679" xyz="0.01432621 0.0755071 -0.00245783"/>
		<axis xyz="0 0 1"/>
		<parent link="LeftShoulderPitchLink"/>
		<child link="LeftShoulderPitchIMULink"/>
	</joint>
	<gazebo reference="LeftShoulderPitchIMULink">
		<sensor name="LeftShoulderPitchIMU" type="imu">
			<always_on>true</always_on>
			<imu>
				<noise>
					<type>gaussian</type>
					<rate>
						<mean>0</mean>
						<stddev>0.0002</stddev>
						<bias_mean>7.5e-06</bias_mean>
						<bias_stddev>8e-07</bias_stddev>
					</rate>
					<accel>
						<mean>0</mean>
						<stddev>0.017</stddev>
						<bias_mean>0.1</bias_mean>
						<bias_stddev>0.001</bias_stddev>
					</accel>
				</noise>
			</imu>
		</sensor>
	</gazebo>

	<!-- Left ShoulderYaw IMU Note: in CAD this is the left bicep IMU -->
	<link name="LeftShoulderYawIMULink">
		<inertial>
			<mass value="0"/>
			<origin rpy="0 0 0" xyz="0 0 0"/>
			<inertia ixx="0.0" ixy="0.0" ixz="0.0" iyy="0.0" iyz="0.0" izz="0.0"/>
		</inertial>
	</link>
	<joint name="LeftShoulderYawIMUJoint" type="fixed">
		<origin rpy="1.570796 3.1415926 -0.314159" xyz="-0.00633723 -0.00669505 -0.19881468"/>
		<axis xyz="0 0 1"/>
		<parent link="LeftShoulderYawLink"/>
		<child link="LeftShoulderYawIMULink"/>
	</joint>
	<gazebo reference="LeftShoulderYawIMULink">
		<sensor name="LeftShoulderYawIMU" type="imu">
			<always_on>true</always_on>
			<pose>0 0 0 0 0 0</pose>
			<imu>
				<noise>
					<type>gaussian</type>
					<rate>
						<mean>0</mean>
						<stddev>0.0002</stddev>
						<bias_mean>7.5e-06</bias_mean>
						<bias_stddev>8e-07</bias_stddev>
					</rate>
					<accel>
						<mean>0</mean>
						<stddev>0.017</stddev>
						<bias_mean>0.1</bias_mean>
						<bias_stddev>0.001</bias_stddev>
					</accel>
				</noise>
			</imu>
		</sensor>
	</gazebo>

	<!-- Left Wrist Yaw IMU Note: in CAD this is the left bicep IMU -->
	<link name="LeftWristYawIMULink">
		<inertial>
			<mass value="0"/>
			<origin rpy="0 0 0" xyz="0 0 0"/>
			<inertia ixx="0.0" ixy="0.0" ixz="0.0" iyy="0.0" iyz="0.0" izz="0.0"/>
		</inertial>
	</link>

	<joint name="LeftWristYawIMUJoint" type="fixed">
		<origin rpy="1.571  0.0 1.571" xyz="-0.048986 0.011658 -0.149476"/>
		<axis xyz="0 0 1"/>
		<parent link="LeftWristYawLink"/>
		<child link="LeftWristYawIMULink"/>
	</joint>

	<gazebo reference="LeftWristYawIMULink">
		<sensor name="LeftWristYawIMU" type="imu">
			<always_on>true</always_on>
			<imu> <!-- placeholder tag for IMU --> </imu>
		</sensor>
	</gazebo>

	<!-- RIGHT ARM -->
	<!-- Right Upper Arm Joints -->
	<joint name="RightShoulderPitch" type="revolute">
		<origin xyz="0 -0.10337060 0.21502827" rpy="-0.698132 0.0 0.0"   />
		<axis xyz="0.0 1.0 0.0" />
		<parent link="Torso" />
		<child link="RightShoulderPitchLink" />
		<limit effort="1000" lower="-3.141592" upper="1.22173" velocity = "100" />
		<dynamics damping="0.05" friction="0.0"/>
	</joint>
	<joint name="RightShoulderRoll" type="revolute">
		<origin rpy="0.698132 0.0 0.0" xyz="0.0 -0.15676000 -0.01300000" />
		<axis xyz="1 0 0" />
		<parent link="RightShoulderPitchLink" />
		<child link="RightShoulderRollLink" />
		<limit effort="1000" lower="-2.79253" upper="0.349066" velocity = "100" />
		<dynamics damping="0.05" friction="0.0"/>
	</joint>
	<joint name="RightShoulderYaw" type="revolute">
		<origin rpy="0.0 0.0 0.0" xyz="0.0 -0.035 0.0" />
		<axis xyz="0.0 0.0 1.0" />
		<parent link="RightShoulderRollLink" />
		<child link="RightShoulderYawLink" />
		<limit effort="1000" lower="-1.22173" upper="1.91986" velocity = "100" />
		<dynamics damping="0.05" friction="0.0"/>
	</joint>
	<joint name="RightElbowPitch" type="revolute">
		<origin rpy="0.0 0.0 0.0" xyz="0.015 0.0 -0.3127" />
		<axis xyz="0.0 1.0 0.0" />
		<parent link="RightShoulderYawLink" />
		<child link="RightElbowPitchLink" />
		<limit effort="1000" lower="-2.35619" upper="0.174532925" velocity = "100" />
		<dynamics damping="0.05" friction="0.0"/>
	</joint>

	<!-- Right wrist joints -->
	<joint name="RightWristYaw" type="revolute">
		<origin xyz="-0.015 0.0 0.0" rpy="0.0 0.0 0.0"   />
		<axis xyz="0.0 0.0 1.0" />
		<parent link="RightElbowPitchLink" />
		<child link="RightWristYawLink" />
		<limit effort="20.0" lower="-2.61799" upper="2.61799" velocity = "25.0" />
		<dynamics damping="0.05" friction="0.0"/>
	</joint>

	<joint name="RightWristRoll" type="revolute">
		<origin xyz="0.0 0.013 -0.25" rpy="0.0 0.0 0.0"/>
		<axis xyz="1 0 0" />
		<parent link="RightWristYawLink" />
		<child link="RightWristRollLink" />
		<limit effort="20.0" lower="-0.610865" upper="1.8326" velocity = "25.0" />
		<dynamics damping="0.05" friction="0.0"/>
	</joint>

	<joint name="RightGripperYaw" type="revolute">
		<origin xyz="0.0 -0.013 -0.031" rpy="0.0 0.0 0.0" />
		<axis xyz="0.0 0.0 1.0" />
		<parent link="RightWristRollLink" />
		<child link="RightGripperYawLink" />
		<limit effort="20.0" lower="-2.61799" upper="2.61799" velocity = "25.0" />
		<dynamics damping="0.05" friction="0.0"/>
	</joint>

	<!-- Right Upper Arm Links -->
	<link name="RightShoulderPitchLink">
		<inertial>
			<mass value="2.99"/>
			<origin rpy="0 0 0" xyz="-0.00264 -0.12135 -0.006824"/>
			<inertia ixx="0.0110394" ixy="-0.0003041" ixz="-0.0000594" iyy="0.0051097" iyz="-0.0009183" izz="0.0116925" />
		</inertial>
		<visual>
			<geometry>
				<mesh filename="package://phantom_description/meshes/cycloidal_arm/RightShoulderPitchLink.obj"/>
			</geometry>
			<origin rpy="0.0 0.0 0.0" xyz="0.0 0.0 0.0"/>
		</visual>
	</link>

	<link name="RightShoulderRollLink">
		<inertial>
			<mass value="0.972"/>
			<origin rpy="0 0 0" xyz="0.012489 -0.01882 -0.0385"/>
			<inertia ixx="0.002949" ixy="-0.000135" ixz="-0.0003358" iyy="0.0023603" iyz="-0.0005249" izz="0.0014377" />
		</inertial>
		<visual>
			<geometry>
				<mesh filename="package://phantom_description/meshes/cycloidal_arm/RightShoulderRollLink_shortBicep.obj"/>
			</geometry>
			<origin rpy="0.0 0.0 0.0" xyz="0.0 0.0 0.0"/>
		</visual>
	</link>

	<link name="RightShoulderYawLink">
		<inertial>
			<mass value="2.91"/>
			<origin rpy="0 0 0" xyz="0.00524 -0.00274 -0.21745"/>
			<inertia ixx="0.0248699" ixy="0.0000211" ixz="0.0000211" iyy="0.0245973" iyz="-0.0004444" izz="0.0029883" />
		</inertial>
		<visual>
			<geometry>
				<mesh filename="package://phantom_description/meshes/cycloidal_arm/RightShoulderYawLink.obj"/>
			</geometry>
			<origin rpy="0.0 0.0 0.0" xyz="0.0 0.0 0.0867"/>
		</visual>
	</link>

	<!-- right wrist links -->
	<link name="RightElbowPitchLink">
		<inertial>
			<mass value="0.45"/>
			<origin xyz="-0.0127 0.006913 -0.048421" rpy="0 0 0"/>
			<inertia ixx="0.0006446" ixy="-0.0000073" ixz="-0.0000345" iyy="0.000625" iyz="-0.0001257" izz="0.0003922" />
		</inertial>
		<visual>
			<geometry>
				<mesh filename="package://phantom_description/meshes/cycloidal_arm/RightElbowPitchLink.obj"/>
			</geometry>
			<origin rpy="0.0 0.0 0.0" xyz="0.0 0.0 0.0"/>
		</visual>
	</link>

	<link name="RightWristYawLink">
		<inertial>
			<mass value="1.547"/> <!-- This is a measured value. Refer to https://docs.google.com/spreadsheets/d/1VXWFJk3VJUsfkHrDaytB2INq94un1KytIOzcKJD0p44/edit?gid=0#gid=0  -->
			<origin xyz="-0.002616 0.000462 -0.13019" rpy="0 0 0"/>
			<inertia ixx="0.0037805" ixy="-0.0000177" ixz="-0.000025" iyy="0.0040639" iyz="0.00009" izz="0.0015151" />
		</inertial>
		<visual>
			<geometry>
				<mesh filename="package://phantom_description/meshes/cycloidal_arm/RightWristYawLink.obj"/>
			</geometry>
			<origin rpy="0.0 0.0 0.0" xyz="0.0 0.0 0.0"/>
		</visual>
	</link>

	<link name="RightWristRollLink">
		<inertial>
			<mass value="0.909"/> <!-- This is a measured value. Refer to https://docs.google.com/spreadsheets/d/1VXWFJk3VJUsfkHrDaytB2INq94un1KytIOzcKJD0p44/edit?gid=0#gid=0  -->
			<origin xyz="-0.0000481 -0.012143 0.000196" rpy="0 0 0"/>
			<inertia ixx="0.0005535" ixy="0.0000081" ixz="-0.0000231" iyy="0.0005559" iyz="0.0000012" izz="0.0005893" />
		</inertial>
		<visual>
			<geometry>
				<mesh filename="package://phantom_description/meshes/cycloidal_arm/RightWristRollLink.obj"/>
			</geometry>
			<origin rpy="0.0 0.0 0.0" xyz="0.0 0.0 0.0"/>
		</visual>
	</link>

	<link name="RightGripperYawLink">
		<inertial>
			<mass value="0.251"/>
			<origin rpy="0 0 0" xyz="-0.000217 -0.000349 0.009761"/>
			<inertia ixx="0.0000722" ixy="-0.0000016" ixz="-0.0000037" iyy="0.0000747" iyz="0.0000004" izz="0.0000324" />
		</inertial>
		<visual>
			<geometry>
				<mesh filename="package://phantom_description/meshes/cycloidal_arm/RightGripperYawLink.obj"/>
			</geometry>
			<origin rpy="0.0 0.0 0.0" xyz="0.0 0.0 0.0"/>
		</visual>
	</link>
	<!-- Right ARM IMU's -->
	<!-- Right Shoulder Pitch IMU Information -->
	<link name="RightShoulderPitchIMULink">
		<inertial>
			<mass value="0"/>
			<origin rpy="0 0 0" xyz="0 0 0"/>
			<inertia ixx="0.0" ixy="0.0" ixz="0.0" iyy="0.0" iyz="0.0" izz="0.0"/>
		</inertial>
	</link>
	<joint name="RightShoulderPitchIMUJoint" type="fixed">
		<origin rpy="3.141592 0 -1.57079632679" xyz="0.01432621 -0.10001299 -0.00245783"/>
		<axis xyz="0 0 1"/>
		<parent link="RightShoulderPitchLink"/>
		<child link="RightShoulderPitchIMULink"/>
	</joint>
	<gazebo reference="RightShoulderPitchIMULink">
		<sensor name="RightShoulderPitchIMU" type="imu">
			<always_on>true</always_on>
			<imu>
				<noise>
					<type>gaussian</type>
					<rate>
						<mean>0</mean>
						<stddev>0.0002</stddev>
						<bias_mean>7.5e-06</bias_mean>
						<bias_stddev>8e-07</bias_stddev>
					</rate>
					<accel>
						<mean>0</mean>
						<stddev>0.017</stddev>
						<bias_mean>0.1</bias_mean>
						<bias_stddev>0.001</bias_stddev>
					</accel>
				</noise>
			</imu>
		</sensor>
	</gazebo>

	<!-- Right ShoulderYaw IMU Note: in CAD this is the left bicep IMU -->
	<link name="RightShoulderYawIMULink">
		<inertial>
			<mass value="0"/>
			<origin rpy="0 0 0" xyz="0 0 0"/>
			<inertia ixx="0.0" ixy="0.0" ixz="0.0" iyy="0.0" iyz="0.0" izz="0.0"/>
		</inertial>
	</link>
	<joint name="RightShoulderYawIMUJoint" type="fixed">
		<origin rpy="-1.570796 0.0 0.314159" xyz="0.00119168 0.00914134 -0.19881468"/>
		<axis xyz="0 0 1"/>
		<parent link="RightShoulderYawLink"/>
		<child link="RightShoulderYawIMULink"/>
	</joint>
	<gazebo reference="RightShoulderYawIMULink">
		<sensor name="RightShoulderYawIMU" type="imu">
			<always_on>true</always_on>
			<pose>0 0 0 0 0 0</pose>
			<imu>
				<noise>
					<type>gaussian</type>
					<rate>
						<mean>0</mean>
						<stddev>0.0002</stddev>
						<bias_mean>7.5e-06</bias_mean>
						<bias_stddev>8e-07</bias_stddev>
					</rate>
					<accel>
						<mean>0</mean>
						<stddev>0.017</stddev>
						<bias_mean>0.1</bias_mean>
						<bias_stddev>0.001</bias_stddev>
					</accel>
				</noise>
			</imu>
		</sensor>
	</gazebo>

	<!-- Right Wrist Yaw IMU Note: in CAD this is the left bicep IMU -->
	<link name="RightWristYawIMULink">
		<inertial>
			<mass value="0"/>
			<origin rpy="0 0 0" xyz="0 0 0"/>
			<inertia ixx="0.0" ixy="0.0" ixz="0.0" iyy="0.0" iyz="0.0" izz="0.0"/>
		</inertial>
	</link>

	<joint name="RightWristYawIMUJoint" type="fixed">
		<origin rpy="1.571  0.0 1.571" xyz="-0.048986 0.011658 -0.149476"/>
		<axis xyz="0 0 1"/>
		<parent link="RightWristYawLink"/>
		<child link="RightWristYawIMULink"/>
	</joint>

	<gazebo reference="RightWristYawIMULink">
		<sensor name="RightWristYawIMU" type="imu">
			<always_on>true</always_on>
			<imu> <!-- placeholder tag for IMU --> </imu>
		</sensor>
	</gazebo>

	<!-- Gripper Fixed Joints -->

	<joint name="LeftGrippertAttachmentFixedJoint" type="fixed">
		<origin rpy="0 0 -1.57079632679" xyz="-0.018385 0 -0.01560000"/> <!--<origin rpy="3.141592 0 0" xyz="0 0 -0.02560000"/>-->
		<parent link="LeftGripperYawLink"/>
		<child link="LeftPsyonicHand"/>
	</joint>
	<joint name="RightGrippertAttachmentFixedJoint" type="fixed">
		<origin rpy="0 0 1.57079632679" xyz="-0.018385 0 -0.01560000"/> <!--<origin rpy="-3.141592 0 3.141592" xyz="0 0 -0.01560000"/>-->
		<parent link="RightGripperYawLink"/>
		<child link="RightPsyonicHand"/>
	</joint>

	<!-- HAND LINKS -->
	<!-- Left Psyonic Ability Hand -->
	<link name="LeftPsyonicHand">
		<inertial>	<!-- the mass is approximate and the inertia is likely incorrect -->
			<mass value = "0.560"/>
			<inertia ixx="0.0011067" ixy="-0.0001015" ixz="0.0000509" iyy="0.0008085" iyz="-0.0000053" izz="0.0004947" />
			<origin rpy = "0 0 0" xyz="0.004676 -0.006268 -0.063361"/>
		</inertial>
		<visual name="PsyonicLeft">
<!--			<origin rpy = "0 0 0" xyz="0 0 0"/>--> <!-- original orientation -->
			<origin rpy = "0 0 1.57079632679" xyz="0 0 0"/>
			<geometry>
				<mesh filename="package://ability_hand_description/models/PsyonicLeft.obj"/>
			</geometry>
		</visual>
	</link>

	<link name="RightPsyonicHand">
		<inertial>	<!-- the mass is approximate and the inertia is likely incorrect -->
			<mass value = "0.560"/>
			<inertia ixx="0.0011067" ixy="0.0001015" ixz="0.0000509" iyy="0.0008085" iyz="0.0000053" izz="0.0004947" />
			<origin rpy = "0 0 0" xyz="0.004676 0.006268 -0.063361"/>
		</inertial>
		<visual name="PsyonicRight">
<!--			<origin rpy = "0 0 3.14" xyz="0 0 0"/>--> <!-- original orientation -->
			<origin rpy = "0 0 1.57079632679" xyz="0 0 0"/>
			<geometry>
				<mesh filename="package://ability_hand_description/models/PsyonicRight.obj"/>
			</geometry>
		</visual>
	</link>
</robot>
