<?xml version = "1.0" ?>
<robot name="phantom">

    <!-- TODO (CD): Update joint, velocity, and effort limits. -->

    <!-- NECK JOINTS -->
    <joint name="NeckYaw" type="revolute">
        <origin rpy="0 0 0" xyz="0 0 0.307953"/> <!-- placeholder for the joint location -->
        <axis xyz="0 0 1"/>
        <parent link="Torso"/>
        <child link="NeckYawLink"/>
        <limit effort="20" lower="-1.5708" upper="1.5708" velocity="20"/>
        <dynamics damping="0.05" friction="0.0"/>
    </joint>
    <joint name="NeckPitch" type="revolute">
        <origin rpy="0 0 0" xyz="0.025 0.01 0.207252"/>
        <axis xyz="0 1 0"/>
        <parent link="NeckYawLink"/>
        <child link="Head"/>
        <limit effort="20" lower="-1.0472" upper="1.0472" velocity="20"/>
        <dynamics damping="0.05" friction="0.0"/>
    </joint>

    <!-- SPINE JOINTS -->
    <joint name="SpineRoll" type="revolute">
        <origin rpy="0 0 0" xyz="-0.110 0 0.045"/>
        <axis xyz="1 0 0"/>
        <parent link="Pelvis"/>
        <child link="SpineRollLink"/>
        <limit effort="250.0" lower="-0.523599" upper="0.523599" velocity="6.0"/>
        <dynamics damping="0.05" friction="0.0"/>
    </joint>
    <joint name="SpineYaw" type="revolute">
        <origin rpy="0 0 0" xyz="0.110 0 0"/>
        <axis xyz="0 0 1"/>
        <parent link="SpineRollLink"/>
        <child link="Torso"/>
        <limit effort="150" lower="-0.5235987756" upper="0.5235987756" velocity="9.0"/>
        <dynamics damping="0.05" friction="0.0"/>
    </joint>

    <!-- LEFT LEG JOINTS -->
    <joint name="LeftHipPitch" type="revolute">
        <!-- oblique hip pitch at 20 degrees from normal pitch axis -->
        <origin rpy="-0.349066 0 0" xyz="0    0.0525  -0.070"/>
        <axis xyz="0 1 0"/>
        <parent link="Pelvis"/>
        <child link="LeftHipPitchLink"/>
        <limit effort="300" lower="-2.61799" upper="0.785398" velocity="8"/>
        <dynamics damping="0.05" friction="0.0"/>
    </joint>
    <joint name="LeftHipRoll" type="revolute">
        <origin rpy="0.349066 0 0" xyz="0	0.087795	0"/>
        <axis xyz="1 0 0"/>
        <parent link="LeftHipPitchLink"/>
        <child link="LeftHipRollLink"/>
        <limit effort="300" lower="-0.3490658504 " upper="0.872664626" velocity="9"/>
        <dynamics damping="0.05" friction="0.0"/>
    </joint>
    <joint name="LeftHipYaw" type="revolute">
        <origin rpy="0 0 0" xyz="0	0	-0.089972"/>
        <axis xyz="0 0 1"/>
        <parent link="LeftHipRollLink"/>
        <child link="LEFT_THIGH"/>
        <limit effort="300" lower="-1.5" upper="1.5" velocity="11"/>
        <dynamics damping="0.05" friction="0.0"/>
    </joint>
    <joint name="LeftKneePitch" type="revolute">
        <origin rpy="0 0 0" xyz="-0.040  -0.013	-0.299953"/>
        <axis xyz="0 1 0"/>
        <parent link="LEFT_THIGH"/>
        <child link="LEFT_SHIN"/>
        <limit effort="300" lower="0" upper="2.445206282" velocity="8"/>
        <dynamics damping="0.05" friction="0.0"/>
    </joint>
    <joint name="LeftAnklePitch" type="revolute">
        <origin rpy="0 0 0" xyz="0.040	0	-0.553"/>
        <axis xyz="0 1 0"/>
        <parent link="LEFT_SHIN"/>
        <child link="LeftAnklePitchLink"/>
        <limit effort="180" lower="-1.0472" upper="0.523599" velocity="8"/>
        <dynamics damping="0.05" friction="0.0"/>
    </joint>
    <joint name="LeftAnkleRoll" type="revolute">
        <origin rpy="0 0 0" xyz="0	0	-0.010"/>
        <axis xyz="1 0 0"/>
        <parent link="LeftAnklePitchLink"/>
        <child link="LeftFoot"/>
        <limit effort="90" lower="-0.436332" upper="0.436332" velocity="8"/>
        <dynamics damping="0.05" friction="0.0"/>
    </joint>

    <!-- RIGHT LEG JOINTS -->
    <joint name="RightHipPitch" type="revolute">
        <!-- oblique hip pitch at 20 degrees from normal pitch axis -->
        <origin rpy="0.349066 0 0" xyz="0.0	-0.0525	-0.070"/>
        <axis xyz="0 1 0"/>
        <parent link="Pelvis"/>
        <child link="RightHipPitchLink"/>
        <limit effort="300" lower="-2.61799" upper="0.785398" velocity="8"/>
        <dynamics damping="0.05" friction="0.0"/>
    </joint>
    <joint name="RightHipRoll" type="revolute">
        <origin rpy="-0.349066 0 0" xyz="0    -0.087795  0"/>
        <axis xyz="1 0 0"/>
        <parent link="RightHipPitchLink"/>
        <child link="RightHipRollLink"/>
        <limit effort="300" lower="-0.872664626" upper="0.3490658504" velocity="9"/>
        <dynamics damping="0.05" friction="0.0"/>
    </joint>
    <joint name="RightHipYaw" type="revolute">
        <origin rpy="0 0 0" xyz="0	0	-0.089972"/>
        <axis xyz="0 0 1"/>
        <parent link="RightHipRollLink"/>
        <child link="RIGHT_THIGH"/>
        <limit effort="300" lower="-1.5" upper="1.5" velocity="11"/>
        <dynamics damping="0.05" friction="0.0"/>
    </joint>
    <joint name="RightKneePitch" type="revolute">
        <origin rpy="0 0 0" xyz="-0.040  0.013	-0.299953"/>
        <axis xyz="0 1 0"/>
        <parent link="RIGHT_THIGH"/>
        <child link="RIGHT_SHIN"/>
        <limit effort="300" lower="0" upper="2.445206282" velocity="8"/>
        <dynamics damping="0.05" friction="0.0"/>
    </joint>
    <joint name="RightAnklePitch" type="revolute">
        <origin rpy="0 0 0" xyz="0.040	0	-0.553"/>
        <axis xyz="0 1 0"/>
        <parent link="RIGHT_SHIN"/>
        <child link="RightAnklePitchLink"/>
        <limit effort="180" lower="-1.0472" upper="0.523599" velocity="8"/>
        <dynamics damping="0.05" friction="0.0"/>
    </joint>
    <joint name="RightAnkleRoll" type="revolute">
        <origin rpy="0 0 0" xyz="0	0	-0.010"/>
        <axis xyz="1 0 0"/>
        <parent link="RightAnklePitchLink"/>
        <child link="RightFoot"/>
        <limit effort="90" lower="-0.436332" upper="0.436332" velocity="8"/>
        <dynamics damping="0.05" friction="0.0"/>
    </joint>


    <!-- LINKS -->
    <link name="Pelvis">
        <inertial>
            <mass value="9.5"/>
            <origin rpy="0 0 0" xyz="0 0 0"/>
            <inertia ixx="0.03428688" ixy="0.00001151" ixz="0.00015935" iyy="0.05178848" iyz="0.00004514" izz="0.06001929"/>
        </inertial>
        <visual>
            <geometry>
                <mesh filename="package://phantom_description/meshes/legs/Pelvis.obj"/>
            </geometry>
            <origin rpy="0.0 0.0 0.0" xyz="0.0 0.0 0.0"/>
        </visual>
    </link>
    <!-- pelvis_stim_imu -->
    <joint name="PelvisStimIMUFixedJoint" type="fixed">
        <parent link="Pelvis"/>
        <child link="PelvisStimIMUMount"/>
        <origin xyz="-0.03133646 0.02237500 -0.07000000" rpy="0.0 3.141592 0.0"/>
    </joint>

    <link name="PelvisStimIMUMount">
        <inertial>
            <mass value="0.0"/>
            <origin xyz="0 0 0" rpy="0 0 0"/>
            <inertia ixx="0.0" ixy="0.0" ixz="0.0" iyy="0.0" iyz="0.0" izz="0.0"/>
        </inertial>
    </link>

    <gazebo reference="PelvisStimIMUMount">
        <sensor name="PelvisStimImu" type="imu">
            <always_on>1</always_on>
            <update_rate>1000.0</update_rate>
            <imu>
                <noise>
                    <type>gaussian</type>
                    <rate>
                        <mean>0.0</mean>
                        <stddev>2e-4</stddev>
                        <bias_mean>0.0000075</bias_mean>
                        <bias_stddev>0.0000008</bias_stddev>
                    </rate>
                    <accel>
                        <mean>0.0</mean>
                        <stddev>1.7e-2</stddev>
                        <bias_mean>0.1</bias_mean>
                        <bias_stddev>0.001</bias_stddev>
                    </accel>
                </noise>
            </imu>
        </sensor>
    </gazebo>
    <!-- end pelvis stim imu -->

    <!-- LEFT LEG LINKS -->
    <link name="LeftHipPitchLink">
        <inertial>
            <mass value="2.32977961"/>
            <origin rpy="0 0 0" xyz="0.04350911	0.08708606 -0.03525761"/>
            <inertia ixx="0.00467452" ixy="-0.00058626" ixz="0.00013124" iyy="0.00516613" iyz="0.00048141" izz="0.00553124"/>
        </inertial>
        <!--visual>
            <geometry>
                <mesh filename="package://phantom_description/meshes/legs/LeftHipRollLink.obj"/>
            </geometry>
            <origin rpy="0.0 0.0 0.0" xyz="0.0 0.0 0.0"/>
        </visual-->
    </link>
    <link name="LeftHipRollLink">
        <inertial>
            <mass value="0.77281362"/>
            <origin rpy="0 0 0" xyz="0.04549595	-0.00525571	-0.00937454"/>
            <inertia ixx="0.00317639" ixy="0.00005807" ixz="0.00080598" iyy="0.00345182" iyz="0.00047441" izz="0.00313245"/>
        </inertial>
        <!--visual>
            <geometry>
                <mesh filename="package://phantom_description/meshes/legs/LeftHipYawLink.obj"/>
            </geometry>
            <origin rpy="0.0 0.0 0.0" xyz="0 0 0"/>
        </visual-->
    </link>
    <link name="LEFT_THIGH">
        <inertial>
            <mass value="8.26796596"/>
            <origin rpy="0 0 0" xyz="0.01417302	0.03268781	-0.10548314"/>
            <inertia ixx="0.09264028" ixy="0.00038532" ixz="0.00916409" iyy="0.09733033" iyz="-0.0043516" izz="0.02803877"/>
        </inertial>
        <visual>
            <geometry>
                <mesh filename="package://phantom_description/meshes/legs/LeftThigh.obj"/>
            </geometry>
            <origin rpy="0.0 0.0 0.0" xyz="0 0 0"/>
        </visual>
    </link>
    <link name="LEFT_SHIN">
        <inertial>
            <mass value="6.34159651"/>
            <origin rpy="0 0 0" xyz="0.03807965	-0.00108105	-0.12410027"/>
            <inertia ixx="0.08823148" ixy="-0.00054706" ixz="-0.00634132" iyy="0.09163264" iyz="0.00002714" izz="0.01569601"/>
        </inertial>
        <visual>
            <geometry>
                <mesh filename="package://phantom_description/meshes/legs/LeftShin.obj"/>
            </geometry>
            <origin rpy="0.0 0.0 0.0" xyz="0 0 0"/>
        </visual>
    </link>
    <link name="LeftAnklePitchLink">
        <inertial>
            <mass value="0.05045632"/>
            <origin rpy="0 0 0" xyz="2.94E-07	2.22E-07	-0.00462997"/>
            <inertia ixx="0.00001733" ixy="2.12E-10" ixz="-1.26E-10" iyy="0.00000714" iyz="-2.02E-11" izz="0.00001851"/>
        </inertial>
        <visual>
            <geometry>
                <mesh filename="package://phantom_description/meshes/legs/AnklePitchLink.obj"/>
            </geometry>
            <origin rpy="0.0 0.0 0.0" xyz="0 0 0"/>
        </visual>
    </link>
    <link name="LeftFoot">
        <inertial>
            <mass value="1.28288609"/>
            <origin rpy="0 0 0" xyz="0.03793372	-0.00000219	-0.0443663"/>
            <inertia ixx="0.00131328" ixy="0.00001057" ixz="0.00036242" iyy="0.00385286" iyz="-0.0000069" izz="0.00406301"/>
        </inertial>
        <visual>
            <geometry>
                <mesh filename="package://phantom_description/meshes/legs/Foot.obj"/>
            </geometry>
            <origin rpy="0.0 0.0 0.0" xyz="0 0 0"/>
        </visual>
    </link>


    <!-- RIGHT LEG LINKS -->
    <link name="RightHipPitchLink">
        <inertial>
            <mass value="2.32977248"/>
            <origin rpy="0 0 0" xyz="0.04351957	-0.08688935	-0.03525357"/>
            <inertia ixx="0.00467576" ixy="0.00061004" ixz="0.00013038" iyy="0.00516385" iyz="-0.00047381" izz="0.00552901"/>
        </inertial>
        <!--visual>
            <geometry>
                <mesh filename="package://phantom_description/meshes/legs/RightHipRollLink.obj"/>
            </geometry>
            <origin rpy="0.0 0.0 0.0" xyz="0.0 0.0 0.0"/>
        </visual-->
    </link>
    <link name="RightHipRollLink">
        <inertial>
            <mass value="0.77281055"/>
            <origin rpy="0 0 0" xyz="0.04549274	0.00525784	-0.00937505"/>
            <inertia ixx="0.00317639" ixy="-0.00005765" ixz="0.00080587" iyy="0.00345166" iyz="-0.00047466" izz="0.00313223"/>
        </inertial>
        <!--visual>
            <geometry>
                <mesh filename="package://phantom_description/meshes/legs/RightHipYawLink.obj"/>
            </geometry>
            <origin rpy="0.0 0.0 0.0" xyz="0 0 0"/>
        </visual-->
    </link>
    <link name="RIGHT_THIGH">
        <inertial>
            <mass value="8.27281716"/>
            <origin rpy="0 0 0" xyz="0.01411846	-0.03282392	-0.10542795"/>
            <inertia ixx="0.09273162" ixy="-0.00026689" ixz="0.00921343" iyy="0.09738701" iyz="0.00422485" izz="0.02802165"/>
        </inertial>
        <visual>
            <geometry>
                <mesh filename="package://phantom_description/meshes/legs/RightThigh.obj"/>
            </geometry>
            <origin rpy="0.0 0.0 0.0" xyz="0 0 0"/>
        </visual>
    </link>
    <link name="RIGHT_SHIN">
        <inertial>
            <mass value="6.31087157"/>
            <origin rpy="0 0 0" xyz="0.03807648	0.00113375	-0.12408765"/>
            <inertia ixx="0.08705693" ixy="0.00057277" ixz="-0.00674654" iyy="0.090231" iyz="0.00028332" izz="0.01554032"/>
        </inertial>
        <visual>
            <geometry>
                <mesh filename="package://phantom_description/meshes/legs/RightShin.obj"/>
            </geometry>
            <origin rpy="0.0 0.0 0.0" xyz="0 0 0"/>
        </visual>
    </link>
    <link name="RightAnklePitchLink">
        <inertial>
            <mass value="0.05045632"/>
            <origin rpy="0 0 0" xyz="2.94E-07	2.22E-07	-0.00462997"/>
            <inertia ixx="0.00001733" ixy="2.12E-10" ixz="-1.26E-10" iyy="0.00000714" iyz="-2.02E-11" izz="0.00001851"/>
        </inertial>
        <visual>
            <geometry>
                <mesh filename="package://phantom_description/meshes/legs/AnklePitchLink.obj"/>
            </geometry>
            <origin rpy="0.0 0.0 0.0" xyz="0 0 0"/>
        </visual>
    </link>
    <link name="RightFoot">
        <inertial>
            <mass value="1.28288609"/>
            <origin rpy="0 0 0" xyz="0.03793372	-0.00000219	-0.0443663"/>
            <inertia ixx="0.00131328" ixy="0.00001057" ixz="0.00036242" iyy="0.00385286" iyz="-0.0000069" izz="0.00406301"/>
        </inertial>
        <visual>
            <geometry>
                <mesh filename="package://phantom_description/meshes/legs/Foot.obj"/>
            </geometry>
            <origin rpy="0.0 0.0 0.0" xyz="0 0 0"/>
        </visual>
    </link>


    <!-- SPINE LINKS -->
    <link name="SpineRollLink">
        <inertial>
            <mass value="0.91"/>
            <origin rpy="0 0 0" xyz="-0.00853118	-2.697E-05	0.03791445"/>
            <inertia ixx="0.00374289408" ixy="1.25497934E-07" ixz="0.000271325072" iyy="0.00403002777" iyz="-1.38015692E-07" izz="0.0062129847"/>
        </inertial>
        <visual>
            <geometry>
                <cylinder radius="0.05" length="0.1"/>
            </geometry>
            <material name="gray">
                <color rgba="0.5 0.5 0.5 1.0"/>
            </material>
            <origin rpy="0.0 0.0 0.0" xyz="0 0 0.05"/>
        </visual>
    </link>
    <link name="Torso">
        <inertial>
            <mass value="30.0"/> <!-- Increased by a random number to account for a battery. Was 13.5, which was also a guess. -->
            <origin rpy="0 0 0" xyz="-0.03613868 -2.81E-06 0.25908586"/>
            <inertia ixx="0.534504681" ixy="8.41519717E-05" ixz="-0.00672956305" iyy="0.505409852" iyz="0.000207996773" izz="0.379402013"/>
        </inertial>
        <visual>
            <geometry>
                <mesh filename="package://phantom_description/meshes/Torso.obj"/>
            </geometry>
            <origin rpy="0.0 0.0 0.0" xyz="0.0 0.0 0.0"/>
        </visual>
    </link>

    <!-- NECK & Head LINKS -->

    <link name="NeckYawLink">
        <inertial>
            <mass value="1.141"/>
            <origin rpy="0 0 0" xyz="0.007143 0.006943 0.109823"/>
            <inertia ixx="0.007475898" ixy="-0.000075723" ixz="-0.000745362" iyy="0.007407578" iyz="-0.000436948" izz="0.00109269" />
        </inertial>
        <visual>
            <geometry>
                <cylinder radius="0.05" length="0.1"/>
            </geometry>
            <material name="gray">
                <color rgba="0.5 0.5 0.5 1.0"/>
            </material>
            <origin rpy="0.0 0.0 0.0" xyz="0 0 0.0"/>
        </visual>
    </link>
    <link name="Head">
        <inertial>
            <mass value="1.677"/>
            <origin rpy="0 0 0" xyz="0.03237 -0.013568 0.007163"/>
            <inertia ixx="0.006026191" ixy="-0.000197484" ixz="0.001813659" iyy="0.008182071" iyz="-0.000042529" izz="0.00644909"/>
        </inertial>
        <visual>
            <geometry>
                <mesh filename="package://phantom_description/meshes/ALX02_01_A02_HeadLink.obj"/>
            </geometry>
            <origin rpy="0.0 0.0 0.0" xyz="0.0 0.0 0.0"/>
        </visual>
    </link>


    <!-- Left Arm -->
    <joint name="LeftShoulderPitch" type="revolute">
        <origin xyz="0.0 0.120 0.235" rpy="0.698132 0.0 0.0"/>
        <axis xyz="0.0 1.0 0.0"/>
        <parent link="Torso"/>
        <child link="LeftShoulderPitchLink"/>
        <limit effort="150.0" lower="-3.141592" upper="1.22173" velocity="9.0"/>
        <dynamics damping="0.05" friction="0.0"/>
    </joint>

    <link name="LeftShoulderPitchLink">
        <inertial>
            <mass value="2.99"/>
            <origin rpy="0 0 0" xyz="-0.00264 0.12135 -0.006824"/>
            <inertia ixx="0.0111046" ixy="0.0002882" ixz="-0.000054" iyy="0.0051699" iyz="0.0009318" izz="0.01176"/>
        </inertial>
        <visual>
            <geometry>
                <mesh filename="package://phantom_description/meshes/cycloidal_arm/LeftShoulderPitchLink.obj"/>
            </geometry>
            <origin rpy="0.0 0.0 0.0" xyz="0.0 0.0 0.0"/>
        </visual>
    </link>

    <joint name="LeftShoulderRoll" type="revolute">
        <origin rpy="-0.698132 0.0 0.0" xyz="0.0 0.140 0.0"/>
        <axis xyz="1 0 0"/>
        <parent link="LeftShoulderPitchLink"/>
        <child link="LeftShoulderRollLink"/>
        <limit effort="150.0" lower="-0.349066" upper="2.79253" velocity="9.0"/>
        <dynamics damping="0.05" friction="0.0"/>
    </joint>

    <link name="LeftShoulderRollLink">
        <inertial>
            <mass value="0.972"/>
            <origin rpy="0 0 0" xyz="0.01251711 0.0188309 -0.03849849"/>
            <inertia ixx="0.0029485" ixy="0.0001386" ixz="-0.0003345" iyy="0.0023587" iyz="0.0005255" izz="0.0014366"/>
        </inertial>
        <visual>
            <geometry>
                <mesh filename="package://phantom_description/meshes/cycloidal_arm/LeftShoulderRollLink_shortBicep.obj"/>
            </geometry>
            <origin rpy="0.0 0.0 0.0" xyz="0.0 0.0 0.0"/>
        </visual>
    </link>

    <joint name="LeftShoulderYaw" type="revolute">
        <origin rpy="0.0 0.0 0.0" xyz="0.0 0.035 0.0"/>
        <axis xyz="0.0 0.0 1.0"/>
        <parent link="LeftShoulderRollLink"/>
        <child link="LeftShoulderYawLink"/>
        <limit effort="80.0" lower="-1.91986" upper="1.22173" velocity="11.5"/>
        <dynamics damping="0.05" friction="0.0"/>
    </joint>

    <link name="LeftShoulderYawLink">
        <inertial>
            <mass value="2.91"/>
            <origin rpy="0 0 0" xyz="0.00510403 0.00314332 -0.21695413"/>
            <inertia ixx="0.0267829" ixy="-0.000011" ixz="0.0015998" iyy="0.0265514" iyz="0.0004426" izz="0.003052"/>
        </inertial>
        <visual>
            <geometry>
                <mesh filename="package://phantom_description/meshes/cycloidal_arm/LeftShoulderYawLink.obj"/>
            </geometry>
            <origin rpy="0.0 0.0 0.0" xyz="0.0 0.0 0.0867"/>
        </visual>
    </link>

    <joint name="LeftElbowPitch" type="revolute">
        <origin rpy="0.0 0.0 0.0" xyz="0.015 0.0 -0.3127"/>
        <axis xyz="0.0 1.0 0.0"/>
        <parent link="LeftShoulderYawLink"/>
        <child link="LeftElbowPitchLink"/>
        <limit effort="80.0" lower="-2.35619" upper="0.174532925" velocity="11.5"/>
        <dynamics damping="0.05" friction="0.0"/>
    </joint>

    <link name="LeftElbowPitchLink">
        <inertial>
            <mass value="0.45"/>
            <origin rpy="0 0 0" xyz="-0.01180322 -0.0035763 -0.04946747"/>
            <inertia ixx="0.0007362" ixy="-0.0000088" ixz="-0.0000292" iyy="0.0006567" iyz="0.0001499" izz="0.0004897"/>
        </inertial>
        <visual>
            <geometry>
                <mesh filename="package://phantom_description/meshes/cycloidal_arm/LeftElbowPitchLink.obj"/>
            </geometry>
            <origin rpy="0.0 0.0 0.0" xyz="0.0 0.0 0.0"/>
        </visual>
    </link>

    <joint name="LeftWristYaw" type="revolute">
        <origin xyz="0.0 0.0 -0.080" rpy="0.0 0.0 0.0"/>
        <axis xyz="0.0 0.0 1.0"/>
        <parent link="LeftElbowPitchLink"/>
        <child link="LeftWristYawLink"/>
        <limit effort="20.0" lower="-2.61799" upper="2.61799" velocity="25.0"/>
        <dynamics damping="0.05" friction="0.0"/>
    </joint>

    <link name="LeftWristYawLink">
        <inertial>
            <mass value="1.547"/> <!-- This is a measured value. Refer to https://docs.google.com/spreadsheets/d/1VXWFJk3VJUsfkHrDaytB2INq94un1KytIOzcKJD0p44/edit?gid=0#gid=0  -->
            <origin rpy="0 0 0" xyz="-0.00263832 -0.00050534 -0.13018376"/>
            <inertia ixx="0.0037869" ixy="0.0000163" ixz="-0.0000252" iyy="0.004071" iyz="-0.0000924" izz="0.0015203"/>
        </inertial>
        <!--visual>
            <geometry>
                <mesh filename="package://phantom_description/meshes/cycloidal_arm/LeftWristYawLink.obj"/>
            </geometry>
            <origin rpy="0.0 0.0 0.0" xyz="0.0 0.0 0.0"/>
        </visual-->
    </link>

    <joint name="LeftWristPitch" type="revolute">
        <origin xyz="0.0 0.0 -0.130" rpy="0.0 0.0 0.0"/>
        <axis xyz="0 1 0"/>
        <parent link="LeftWristYawLink"/>
        <child link="LeftWristPitchLink"/>
        <limit effort="20.0" lower="-1.8326" upper="0.610865" velocity="25.0"/>
        <dynamics damping="0.05" friction="0.0"/>
    </joint>

    <link name="LeftWristPitchLink">
        <inertial>
            <mass value="0.909"/> <!-- This is a measured value. Refer to https://docs.google.com/spreadsheets/d/1VXWFJk3VJUsfkHrDaytB2INq94un1KytIOzcKJD0p44/edit?gid=0#gid=0  -->
            <origin rpy="0 0 0" xyz="0.00004053 0.01038395 0.00035532"/>
            <inertia ixx="0.000477" ixy="-0.0000079" ixz="-0.0000097" iyy="0.0004902" iyz="-0.0000008" izz="0.000514"/>
        </inertial>
        <visual>
            <geometry>
                <mesh filename="package://phantom_description/meshes/cycloidal_arm/LeftWristRollLink.obj"/>
            </geometry>
            <origin rpy="0.0 0.0 0.0" xyz="0.0 0.0 0.0"/>
        </visual>
    </link>

    <joint name="LeftWristRoll" type="revolute">
        <origin xyz="0.0 0.013 -0.031" rpy="0.0 0.0 0.0"/>
        <axis xyz="1 0 0"/>
        <parent link="LeftWristPitchLink"/>
        <child link="LeftWristRollLink"/>
        <limit effort="20.0" lower="-2.61799" upper="2.61799" velocity="25.0"/>
        <dynamics damping="0.05" friction="0.0"/>
    </joint>

    <link name="LeftWristRollLink">
        <inertial>
            <mass value="0.251"/>
            <origin
                    rpy="0 0 0"
                    xyz="-0.000217 -0.000349 0.009761"/>
            <inertia ixx="0.0000722" ixy="-0.0000016" ixz="-0.0000037" iyy="0.0000747" iyz="0.0000004" izz="0.0000324"/>
        </inertial>
        <visual>
            <geometry>
                <mesh filename="package://phantom_description/meshes/cycloidal_arm/nub.obj"/>
            </geometry>
            <origin rpy="0.0 1.57 0.0" xyz="0.0 0.0 0.0"/>
        </visual>
    </link>


    <!-- Right Arm -->
    <joint name="RightShoulderPitch" type="revolute">
        <origin xyz="0.0 -0.120 0.235" rpy="-0.698132 0.0 0.0"/>
        <axis xyz="0.0 1.0 0.0"/>
        <parent link="Torso"/>
        <child link="RightShoulderPitchLink"/>
        <limit effort="1000" lower="-3.141592" upper="1.22173" velocity="100"/>
        <dynamics damping="0.05" friction="0.0"/>
    </joint>

    <link name="RightShoulderPitchLink">
        <inertial>
            <mass value="2.99"/>
            <origin rpy="0 0 0" xyz="-0.00264 -0.12135 -0.006824"/>
            <inertia ixx="0.0110394" ixy="-0.0003041" ixz="-0.0000594" iyy="0.0051097" iyz="-0.0009183" izz="0.0116925"/>
        </inertial>
        <visual>
            <geometry>
                <mesh filename="package://phantom_description/meshes/cycloidal_arm/RightShoulderPitchLink.obj"/>
            </geometry>
            <origin rpy="0.0 0.0 0.0" xyz="0.0 0.0 0.0"/>
        </visual>
    </link>

    <joint name="RightShoulderRoll" type="revolute">
        <origin rpy="0.698132 0.0 0.0" xyz="0.0 -0.140 0.0"/>
        <axis xyz="1 0 0"/>
        <parent link="RightShoulderPitchLink"/>
        <child link="RightShoulderRollLink"/>
        <limit effort="1000" lower="-2.79253" upper="0.349066" velocity="100"/>
        <dynamics damping="0.05" friction="0.0"/>
    </joint>

    <link name="RightShoulderRollLink">
        <inertial>
            <mass value="0.972"/>
            <origin rpy="0 0 0" xyz="0.012489 -0.01882 -0.0385"/>
            <inertia ixx="0.002949" ixy="-0.000135" ixz="-0.0003358" iyy="0.0023603" iyz="-0.0005249" izz="0.0014377"/>
        </inertial>
        <visual>
            <geometry>
                <mesh filename="package://phantom_description/meshes/cycloidal_arm/RightShoulderRollLink_shortBicep.obj"/>
            </geometry>
            <origin rpy="0.0 0.0 0.0" xyz="0.0 0.0 0.0"/>
        </visual>
    </link>

    <joint name="RightShoulderYaw" type="revolute">
        <origin rpy="0.0 0.0 0.0" xyz="0.0 -0.035 0.0"/>
        <axis xyz="0.0 0.0 1.0"/>
        <parent link="RightShoulderRollLink"/>
        <child link="RightShoulderYawLink"/>
        <limit effort="1000" lower="-1.22173" upper="1.91986" velocity="100"/>
        <dynamics damping="0.05" friction="0.0"/>
    </joint>

    <link name="RightShoulderYawLink">
        <inertial>
            <mass value="2.91"/>
            <origin rpy="0 0 0" xyz="0.00524 -0.00274 -0.21745"/>
            <inertia ixx="0.0248699" ixy="0.0000211" ixz="0.0000211" iyy="0.0245973" iyz="-0.0004444" izz="0.0029883"/>
        </inertial>
        <visual>
            <geometry>
                <mesh filename="package://phantom_description/meshes/cycloidal_arm/RightShoulderYawLink.obj"/>
            </geometry>
            <origin rpy="0.0 0.0 0.0" xyz="0.0 0.0 0.0867"/>
        </visual>
    </link>

    <joint name="RightElbowPitch" type="revolute">
        <origin rpy="0.0 0.0 0.0" xyz="0.015 0.0 -0.3127"/>
        <axis xyz="0.0 1.0 0.0"/>
        <parent link="RightShoulderYawLink"/>
        <child link="RightElbowPitchLink"/>
        <limit effort="1000" lower="-2.35619" upper="0.174532925" velocity="100"/>
        <dynamics damping="0.05" friction="0.0"/>
    </joint>

    <link name="RightElbowPitchLink">
        <inertial>
            <mass value="0.45"/>
            <origin xyz="-0.0127 0.006913 -0.048421" rpy="0 0 0"/>
            <inertia ixx="0.0006446" ixy="-0.0000073" ixz="-0.0000345" iyy="0.000625" iyz="-0.0001257" izz="0.0003922"/>
        </inertial>
        <visual>
            <geometry>
                <mesh filename="package://phantom_description/meshes/cycloidal_arm/RightElbowPitchLink.obj"/>
            </geometry>
            <origin rpy="0.0 0.0 0.0" xyz="0.0 0.0 0.0"/>
        </visual>
    </link>

    <joint name="RightWristYaw" type="revolute">
        <origin xyz="0.0 0.0 -0.080" rpy="0.0 0.0 0.0"/>
        <axis xyz="0.0 0.0 1.0"/>
        <parent link="RightElbowPitchLink"/>
        <child link="RightWristYawLink"/>
        <limit effort="20.0" lower="-2.61799" upper="2.61799" velocity="25.0"/>
        <dynamics damping="0.05" friction="0.0"/>
    </joint>

    <link name="RightWristYawLink">
        <inertial>
            <mass value="1.547"/> <!-- This is a measured value. Refer to https://docs.google.com/spreadsheets/d/1VXWFJk3VJUsfkHrDaytB2INq94un1KytIOzcKJD0p44/edit?gid=0#gid=0  -->
            <origin xyz="-0.002616 0.000462 -0.13019" rpy="0 0 0"/>
            <inertia ixx="0.0037805" ixy="-0.0000177" ixz="-0.000025" iyy="0.0040639" iyz="0.00009" izz="0.0015151"/>
        </inertial>
        <!--visual>
            <geometry>
                <mesh filename="package://phantom_description/meshes/cycloidal_arm/RightWristYawLink.obj"/>
            </geometry>
            <origin rpy="0.0 0.0 0.0" xyz="0.0 0.0 0.0"/>
        </visual-->
    </link>

    <joint name="RightWristPitch" type="revolute">
        <origin xyz="0.0 0.0 -0.130" rpy="0.0 0.0 0.0"/>
        <axis xyz="0 1 0"/>
        <parent link="RightWristYawLink"/>
        <child link="RightWristPitchLink"/>
        <limit effort="20.0" lower="-1.8326" upper="0.610865" velocity="25.0"/>
        <dynamics damping="0.05" friction="0.0"/>
    </joint>

    <link name="RightWristPitchLink">
        <inertial>
            <mass value="0.909"/> <!-- This is a measured value. Refer to https://docs.google.com/spreadsheets/d/1VXWFJk3VJUsfkHrDaytB2INq94un1KytIOzcKJD0p44/edit?gid=0#gid=0  -->
            <origin xyz="-0.0000481 -0.012143 0.000196" rpy="0 0 0"/>
            <inertia ixx="0.0005535" ixy="0.0000081" ixz="-0.0000231" iyy="0.0005559" iyz="0.0000012" izz="0.0005893"/>
        </inertial>
        <visual>
            <geometry>
                <mesh filename="package://phantom_description/meshes/cycloidal_arm/RightWristRollLink.obj"/>
            </geometry>
            <origin rpy="0.0 0.0 0.0" xyz="0.0 0.0 0.0"/>
        </visual>
    </link>

    <joint name="RightWristRoll" type="revolute">
        <origin xyz="0.0 -0.013 -0.031" rpy="0.0 0.0 0.0"/>
        <axis xyz="1 0 0"/>
        <parent link="RightWristPitchLink"/>
        <child link="RightWristRollLink"/>
        <limit effort="20.0" lower="-2.61799" upper="2.61799" velocity="25.0"/>
        <dynamics damping="0.05" friction="0.0"/>
    </joint>

    <link name="RightWristRollLink">
        <inertial>
            <mass value="0.251"/>
            <origin rpy="0 0 0" xyz="-0.000217 -0.000349 0.009761"/>
            <inertia ixx="0.0000722" ixy="-0.0000016" ixz="-0.0000037" iyy="0.0000747" iyz="0.0000004" izz="0.0000324"/>
        </inertial>
        <visual>
            <geometry>
                <mesh filename="package://phantom_description/meshes/cycloidal_arm/nub.obj"/>
            </geometry>
            <origin rpy="0.0 1.57 0.0" xyz="0.0 0.0 0.0"/>
        </visual>
    </link>


    <!-- GRIPPER JOINTS AND LINKS -->
    <joint name="rightGrippertAttachmentFixedJoint" type="fixed">
        <origin rpy="-3.141592 0 3.141592" xyz="0 0 -0.02560000"/>
        <parent link="RightWristRollLink"/>
        <child link="RightPsyonicAbilityBaseLink"/>
    </joint>

    <joint name="leftGrippertAttachmentFixedJoint" type="fixed">
        <origin rpy="3.141592 0 0" xyz="0 0 -0.02560000"/>
        <parent link="LeftWristRollLink"/>
        <child link="LeftPsyonicAbilityBaseLink"/>
    </joint>

    <!-- Left Psyonic Ability Hand -->
    <link name="LeftPsyonicAbilityBaseLink">
        <visual name="wrist_mesh">
            <origin rpy="0 0 0" xyz="0 0 0"/>
            <geometry>
                <mesh filename="package://ability_hand_description/models/wristmesh.obj"/>
            </geometry>
        </visual>
        <inertial>    <!-- the mass and inertia here are NOT correct -->
            <mass value="1.00"/>
            <inertia ixx="978.26e-6" ixy="87.34e-6" ixz="322.99e-6" iyy="1244.78e-6" iyz="244.74e-6" izz="456.22e-6"/>
            <origin xyz="22.41911e-3 -0.15798201e-3 -0.01319866e-3" rpy="0 0 0"/>
        </inertial>
    </link>

    <!-- Right Psyonic Ability Hand -->
    <link name="RightPsyonicAbilityBaseLink">
        <visual name="wrist_mesh">
            <origin rpy="0 0 0" xyz="0 0 0"/>
            <geometry>
                <mesh filename="package://ability_hand_description/models/wristmesh.obj"/>
            </geometry>
        </visual>
        <inertial>    <!-- the mass and inertia here are NOT correct -->
            <mass value="1.00"/>
            <inertia ixx="978.26e-6" ixy="87.34e-6" ixz="322.99e-6" iyy="1244.78e-6" iyz="244.74e-6" izz="456.22e-6"/>
            <origin xyz="22.41911e-3 -0.15798201e-3 -0.01319866e-3" rpy="0 0 0"/>
        </inertial>
    </link>

</robot>
